<?xml version="1.0" encoding="utf-8"?>
<!-- This URDF was automatically created by SolidWorks to URDF Exporter! Originally created by Stephen Brawner (brawner@gmail.com) 
     Commit Version: 1.6.0-1-g15f4949  Build Version: 1.6.7594.29634
     For more information, please see http://wiki.ros.org/sw_urdf_exporter -->
<robot
  name="pan_tilt_mech">
  <link
    name="base_link">
    <inertial>
      <origin
        xyz="0 0 0"
        rpy="0 0 0" />
      <mass
        value="0.2918" />
      <inertia
        ixx="0.0012785"
        ixy="7.8447E-20"
        ixz="-6.4806E-19"
        iyy="0.003088"
        iyz="-8.7448E-07"
        izz="0.0026035" />
    </inertial>
    <visual>
      <origin
        xyz="0 0 0"
        rpy="0 0 0" />
      <geometry>
        <mesh
          filename="package://pan_tilt_mech/meshes/base_link.STL" />
      </geometry>
      <material
        name="">
        <color
          rgba="1 1 1 1" />
      </material>
    </visual>
    <collision>
      <origin
        xyz="0 0 0"
        rpy="0 0 0" />
      <geometry>
        <mesh
          filename="package://pan_tilt_mech/meshes/base_link.STL" />
      </geometry>
    </collision>
  </link>
  <link
    name="pan_link">
    <inertial>
      <origin
        xyz="1.249E-16 0.027895 -0.0078715"
        rpy="0 0 0" />
      <mass
        value="0.3185" />
      <inertia
        ixx="0.00099595"
        ixy="-9.0846E-19"
        ixz="1.8127E-18"
        iyy="0.0011829"
        iyz="-6.8855E-06"
        izz="0.00062446" />
    </inertial>
    <visual>
      <origin
        xyz="0 0 0"
        rpy="0 0 0" />
      <geometry>
        <mesh
          filename="package://pan_tilt_mech/meshes/pan_link.STL" />
      </geometry>
      <material
        name="">
        <color
          rgba="1 1 1 0.3" />
      </material>
    </visual>
    <collision>
      <origin
        xyz="0 0 0"
        rpy="0 0 0" />
      <geometry>
        <mesh
          filename="package://pan_tilt_mech/meshes/pan_link.STL" />
      </geometry>
    </collision>
  </link>
  <joint
    name="pan_joint"
    type="revolute">
    <origin
      xyz="0.010936 -0.086324 0.12913"
      rpy="1.5708 0 -1.6005" />
    <parent
      link="base_link" />
    <child
      link="pan_link" />
    <axis
      xyz="0 1 0" />
    <limit
      lower="-3.14"
      upper="3.14"
      effort="10"
      velocity="10" />
  </joint>
  <link
    name="tilt_link">
    <inertial>
      <origin
        xyz="0.005 0.01059 -1.3878E-17"
        rpy="0 0 0" />
      <mass
        value="0.026299" />
      <inertia
        ixx="4.534E-06"
        ixy="1.1948E-20"
        ixz="-1.7033E-20"
        iyy="6.5271E-05"
        iyz="-8.4703E-22"
        izz="6.2741E-05" />
    </inertial>
    <visual>
      <origin
        xyz="0 0 0"
        rpy="0 0 0" />
      <geometry>
        <mesh
          filename="package://pan_tilt_mech/meshes/tilt_link.STL" />
      </geometry>
      <material
        name="">
        <color
          rgba="1 1 1 0.3" />
      </material>
    </visual>
    <collision>
      <origin
        xyz="0 0 0"
        rpy="0 0 0" />
      <geometry>
        <mesh
          filename="package://pan_tilt_mech/meshes/tilt_link.STL" />
      </geometry>
    </collision>
  </link>
  <joint
    name="tilt_joint"
    type="continuous">
    <origin
      xyz="0 0.067 0"
      rpy="2.9341 -1.5708 0" />
    <parent
      link="pan_link" />
    <child
      link="tilt_link" />
    <axis
      xyz="1 0 0" />
    <limit
      lower="-3.14"
      upper="3.14"
      effort="10"
      velocity="10" />
  </joint>
</robot>